<mujoco model="papras">
    <compiler angle="radian" meshdir="meshes/" />
    <size njmax="500" nconmax="100" />
    <asset>
        <mesh name="link1" file="link1.stl" scale="0.001 0.001 0.001" />
        <mesh name="link2" file="link2.stl" scale="0.001 0.001 0.001" />
        <mesh name="link3_papras_simple" file="link3_papras_simple.stl" scale="0.001 0.001 0.001" />
        <mesh name="link4_papras_simple" file="link4_papras_simple.stl" scale="0.001 0.001 0.001" />
        <mesh name="link5" file="link5.stl" scale="0.001 0.001 0.001" />
        <mesh name="link6_papras_simple" file="link6_papras_simple.stl" scale="0.001 0.001 0.001" />
        <mesh name="end_link" file="end_link.stl" scale="0.001 0.001 0.001" />
        <mesh name="gripper_main_link" file="gripper_main_link.stl" scale="0.001 0.001 0.001" />
        <mesh name="gripper_link" file="gripper_link.stl" scale="0.001 0.001 0.001" />
        <mesh name="gripper_sub_link" file="gripper_sub_link.stl" scale="0.001 0.001 0.001" />
        <mesh name="camera_mount_simple" file="camera_mount_simple.stl" />
    </asset>
    <actuator>
        <!-- Physical limits of the actuator. -->
        <motor ctrllimited="true" ctrlrange="-80.0 80.0" joint="robot1/joint1" name="papras_torq_j1"/>
        <motor ctrllimited="true" ctrlrange="-80.0 80.0" joint="robot1/joint2" name="papras_torq_j2"/>
        <motor ctrllimited="true" ctrlrange="-80.0 80.0" joint="robot1/joint3" name="papras_torq_j3"/>
        <motor ctrllimited="true" ctrlrange="-80.0 80.0" joint="robot1/joint4" name="papras_torq_j4"/>
        <motor ctrllimited="true" ctrlrange="-80.0 80.0" joint="robot1/joint5" name="papras_torq_j5"/>
        <motor ctrllimited="true" ctrlrange="-12.0 12.0" joint="robot1/joint6" name="papras_torq_j6"/>
        <position ctrllimited="true" ctrlrange="0.0 0.04" joint="robot1/gripper" kp="1000" name="papras_gripper_finger_joint1" forcelimited="true" forcerange="-20 20"/>
        <position ctrllimited="true" ctrlrange="-0.04 0.0" joint="robot1/gripper_sub" kp="1000" name="papras_gripper_finger_joint2" forcelimited="true" forcerange="-20 20"/>
    </actuator>
    <worldbody>
        <geom type="mesh" mesh="link1" />
        <body name="robot1/link2" pos="0 0 0.126">
            <inertial pos="0 0.0008 0.03183" mass="0.94658" diaginertia="1 1 1" />
            <joint name="robot1/joint1" pos="0 0 0" axis="0 0 1" limited="true" range="-3.14159 3.14159" damping="0.7" />
            <geom type="mesh" mesh="link2" />
            <body name="robot1/link3" pos="0 0.069 0.033">
                <inertial pos="0.01768 -0.06881 0.20524" mass="1.3026" diaginertia="1 1 1" />
                <joint name="robot1/joint2" pos="0 0 0" axis="0 1 0" limited="true" range="-2 2" damping="0.7" />
                <geom pos="0.067 0.008 -0.019" quat="0.000796327 0 0 1" type="mesh" mesh="link3_papras_simple" />
                <body name="robot1/link4" pos="0.03 -0.0115 0.264">
                    <inertial pos="0.12475 -0.05716 0.02979" mass="1.15977" diaginertia="1 1 1" />
                    <joint name="robot1/joint3" pos="0 0 0" axis="0 1 0" limited="true" range="-3.14159 1.5708" damping="0.7" />
                    <geom pos="0.227 0.0085 -0.024" quat="0.000796327 0 0 1" type="mesh" mesh="link4_papras_simple" />
                    <body name="robot1/link5" pos="0.195 -0.0575 0.03">
                        <inertial pos="0.05642 -0.00217 2e-05" mass="0.44688" diaginertia="1 1 1" />
                        <joint name="robot1/joint4" pos="0 0 0" axis="1 0 0" limited="true" range="-2.74889 2.74889" damping="0.7" />
                        <geom type="mesh" mesh="link5" />
                        <body name="robot1/link6" pos="0.063 0.045 0">
                            <inertial pos="0.06831 -0.04457 0" mass="0.43273" diaginertia="1 1 1" />
                            <joint name="robot1/joint5" pos="0 0 0" axis="0 1 0" limited="true" range="-1.5708 1.5708" damping="0.7" />
                            <geom pos="-0.034 -0.098 -0.028" type="mesh" mesh="link6_papras_simple" />
                            <body name="robot1/end_link" pos="0.123 -0.045 0">
                                <inertial pos="0.0155548 0.00238111 0.00634774" quat="0.679934 0.19414 0.420576 0.568433" mass="0.61719" diaginertia="4.00045 4.00045 4.00001" />
                                <joint name="robot1/joint6" pos="0 0 0" axis="1 0 0" limited="true" range="-3.14159 3.14159" damping="0.7" />
                                <geom type="mesh" mesh="end_link" />
                                <geom pos="0.007 0 0" type="mesh" mesh="gripper_main_link" />
                                <geom pos="0.0662 0.0167 0.04452" type="mesh" mesh="camera_mount_simple" />
                                <body name="robot1/gripper_link" pos="0.0622 -0.04 0" quat="0.980067 0 0 -0.198669">
                                    <inertial pos="0 0 0" mass="0.013" diaginertia="1 1 1" />
                                    <joint name="robot1/gripper" pos="0 0 0" axis="0 0 1" limited="true" range="0 1.15" damping="0.1" />
                                    <geom type="mesh" mesh="gripper_link" />
                                </body>
                                <body name="robot1/gripper_sub_link" pos="0.0622 0.04 0" quat="0.980067 0 0 0.198669">
                                    <inertial pos="0 0 0" mass="0.013" diaginertia="1 1 1" />
                                    <joint name="robot1/gripper_sub" pos="0 0 0" axis="0 0 -1" limited="true" range="0 1.15" damping="0.1" />
                                    <geom type="mesh" mesh="gripper_sub_link" />
                                </body>
                            </body>
                        </body>
                    </body>
                </body>
            </body>
        </body>
    </worldbody>
</mujoco>
