<?xml version="1.0" ?>
<!-- =================================================================================== -->
<!-- |    This document was autogenerated by xacro from simple_robot.urdf.xacro        | -->
<!-- |    EDITING THIS FILE BY HAND IS NOT RECOMMENDED                                 | -->
<!-- =================================================================================== -->
<robot name="papras">

  <mujoco>
        <compiler meshdir="meshes/"
                  balanceinertia="true"
                  strippath="false"/>
        <default>
          <default class="arm">
              <joint damping="0.1" />
              <motor ctrllimited="true" />
          </default>
          <default class="gripper">
              <joint damping="0.01" />
              <motor ctrllimited="true" />
          </default>
      </default>
  </mujoco>
  <mujocoinclude>
      <actuator>
          <!-- Physical limits of the actuator. -->
          <motor ctrllimited="true" ctrlrange="-80.0 80.0" joint="robot1/joint1" name="papras_torq_j1"/>
          <motor ctrllimited="true" ctrlrange="-80.0 80.0" joint="robot1/joint2" name="papras_torq_j2"/>
          <motor ctrllimited="true" ctrlrange="-80.0 80.0" joint="robot1/joint3" name="papras_torq_j3"/>
          <motor ctrllimited="true" ctrlrange="-80.0 80.0" joint="robot1/joint4" name="papras_torq_j4"/>
          <motor ctrllimited="true" ctrlrange="-80.0 80.0" joint="robot1/joint5" name="papras_torq_j5"/>
          <motor ctrllimited="true" ctrlrange="-12.0 12.0" joint="robot1/joint6" name="papras_torq_j6"/>
          <position ctrllimited="true" ctrlrange="0.0 0.04" joint="robot1/gripper" kp="1000" name="paparas_gripper" forcelimited="true" forcerange="-20 20"/>
        <position ctrllimited="true" ctrlrange="-0.04 0.0" joint="robot1/gripper_sub" kp="1000" name="papras_gripper_sub" forcelimited="true" forcerange="-20 20"/>
      </actuator>
  </mujocoinclude>
  <!-- PAPRAS URDF Macros -->
  <!-- Main URDF File should contain:
        - world link
        - world-env joint
        - env link
        - env-robotn/link1 joint for each mount -->
  <!-- This file contains URDF geometry, transmission data and Gazebo references -->
  <material name="black">
    <color rgba="0.0 0.0 0.0 1.0"/>
  </material>
  <material name="blue">
    <color rgba="0.0 0.0 0.8 1.0"/>
  </material>
  <material name="green">
    <color rgba="0.0 0.8 0.0 1.0"/>
  </material>
  <material name="grey">
    <color rgba="0.5 0.5 0.5 1.0"/>
  </material>
  <material name="orange">
    <color rgba="1.0 0.4235294117647059 0.0392156862745098 1.0"/>
  </material>
  <material name="brown">
    <color rgba="0.8705882352941177 0.8117647058823529 0.7647058823529411 1.0"/>
  </material>
  <material name="red">
    <color rgba="0.8 0.0 0.0 1.0"/>
  </material>
  <material name="white">
    <color rgba="1.0 1.0 1.0 1.0"/>
  </material>
  <link name="world"/>
  <joint name="robot1/env_arm_fixed" type="fixed">
    <parent link="world"/>
    <child link="robot1/link1"/>
    <origin rpy="0 0 0" xyz="0 0 0"/>
  </joint>
  <!-- link 1 -->
  <link name="robot1/link1">
    <visual>
      <origin rpy="0 0 0" xyz="0 0 0"/>
      <geometry>
        <mesh filename="link1.stl" scale="0.001 0.001 0.001"/>
      </geometry>
      <material name="grey"/>
    </visual>
    <collision>
      <origin rpy="0 0 0" xyz="0 0 0"/>
      <geometry>
        <mesh filename="link1.stl" scale="0.001 0.001 0.001"/>
      </geometry>
    </collision>
    <inertial>
      <origin rpy="0 0 0" xyz="0.00023 0.00000 0.06223"/>
      <mass value="0.85644"/>
      <inertia ixx="1.0" ixy="0.0" ixz="0.0" iyy="1.0" iyz="0.0" izz="1.0"/>
      <!--<inertia ixx="0.00121064" ixy="0.0" ixz="0.00001100" iyy="0.00120886" iyz="0.0" izz="0.00038103" />-->
    </inertial>
  </link>
  <!-- Joint 1 -->
  <joint name="robot1/joint1" type="revolute">
    <parent link="robot1/link1"/>
    <child link="robot1/link2"/>
    <origin rpy="0 0 0" xyz="0.0 0.0 0.126"/>
    <axis xyz="0 0 1"/>
    <limit effort="100" lower="-3.141592653589793" upper="3.141592653589793" velocity="3.03687"/>
    <dynamics damping="0.7"/>
  </joint>
  <!-- link 2 -->
  <link name="robot1/link2">
    <visual>
      <origin rpy="0 0 0" xyz="0 0 0"/>
      <geometry>
        <mesh filename="link2.stl" scale="0.001 0.001 0.001"/>
      </geometry>
      <material name="grey"/>
    </visual>
    <collision>
      <origin rpy="0 0 0" xyz="0 0 0"/>
      <geometry>
        <mesh filename="link2.stl" scale="0.001 0.001 0.001"/>
      </geometry>
    </collision>
    <inertial>
      <origin rpy="0 0 0" xyz="0.00000 0.00080 0.03183"/>
      <!--<origin xyz="0.00000 -0.06820 -0.00117" rpy="0 0 0"/>-->
      <mass value="0.94658"/>
      <inertia ixx="1.0" ixy="0.0" ixz="0.0" iyy="1.0" iyz="0.0" izz="1.0"/>
      <!--<inertia ixx="0.00152547" ixy="0.0" ixz="0.0" iyy="0.00045954" iyz="-0.00001086" izz="0.00151740" />-->
    </inertial>
  </link>
  <!-- Joint 2 -->
  <joint name="robot1/joint2" type="revolute">
    <parent link="robot1/link2"/>
    <child link="robot1/link3"/>
    <origin rpy="0 0 0" xyz="0.0 0.069 0.033"/>
    <axis xyz="0 1 0"/>
    <limit effort="100" lower="-2.0" upper="2.0" velocity="3.03687"/>
    <dynamics damping="0.7"/>
  </joint>
  <!-- link 3 -->
  <link name="robot1/link3">
    <visual>
      <origin rpy="0 0 3.14" xyz="0.067 0.008 -0.019"/>
      <geometry>
        <mesh filename="link3_papras.stl" scale="0.001 0.001 0.001"/>
      </geometry>
      <material name="grey"/>
    </visual>
    <collision>
      <origin rpy="0 0 3.14" xyz="0.067 0.008 -0.019"/>
      <geometry>
        <mesh filename="link3_papras_simple.stl" scale="0.001 0.001 0.001"/>
      </geometry>
    </collision>
    <inertial>
      <origin rpy="0 0 0" xyz="0.01768 -0.06881 0.20524"/>
      <!--<origin xyz="-0.01232 -0.05731 -0.05876" rpy="0 0 0"/>-->
      <mass value="1.30260"/>
      <inertia ixx="1.0" ixy="0.0" ixz="0.0" iyy="1.0" iyz="0.0" izz="1.0"/>
      <!--<inertia ixx="0.01111021" ixy="0.00001331" ixz="-0.00134208" iyy="0.01046642" iyz="0.00016235" izz="0.00202081" />-->
    </inertial>
  </link>
  <!-- Joint 3 -->
  <joint name="robot1/joint3" type="revolute">
    <parent link="robot1/link3"/>
    <child link="robot1/link4"/>
    <origin rpy="0 0 0" xyz="0.03000 -0.01150 0.26400"/>
    <axis xyz="0 1 0"/>
    <limit effort="100" lower="-3.141592653589793" upper="1.5707963267948966" velocity="3.03687"/>
    <dynamics damping="0.7"/>
  </joint>
  <!-- link 4 -->
  <link name="robot1/link4">
    <visual>
      <origin rpy="0 0 3.14" xyz="0.227 0.0085 -0.024"/>
      <geometry>
        <mesh filename="link4_papras.stl" scale="0.001 0.001 0.001"/>
      </geometry>
      <material name="grey"/>
    </visual>
    <collision>
      <origin rpy="0 0 3.14" xyz="0.227 0.0085 -0.024"/>
      <geometry>
        <mesh filename="link4_papras_simple.stl" scale="0.001 0.001 0.001"/>
      </geometry>
    </collision>
    <inertial>
      <origin rpy="0 0 0" xyz="0.12475 -0.05716 0.02979"/>
      <!--<origin xyz="-0.07025 0.00034 -0.00021" rpy="0 0 0"/>-->
      <mass value="1.15977"/>
      <inertia ixx="1.0" ixy="0.0" ixz="0.0" iyy="1.0" iyz="0.0" izz="1.0"/>
      <!--<inertia ixx="0.00096726" ixy="0.00004383" ixz="-0.00002771" iyy="0.00318801" iyz="0.00000627" izz="0.00341484" />-->
    </inertial>
  </link>
  <!-- Joint 4 -->
  <joint name="robot1/joint4" type="revolute">
    <parent link="robot1/link4"/>
    <child link="robot1/link5"/>
    <origin rpy="0 0 0" xyz="0.19500 -0.05750 0.03000"/>
    <axis xyz="1 0 0"/>
    <limit effort="100" lower="-2.748893571891069" upper="2.748893571891069" velocity="3.03687"/>
    <dynamics damping="0.7"/>
  </joint>
  <!-- link 5 -->
  <link name="robot1/link5">
    <visual>
      <origin rpy="0 0 0" xyz="0 0 0"/>
      <geometry>
        <mesh filename="link5.stl" scale="0.001 0.001 0.001"/>
      </geometry>
      <material name="grey"/>
    </visual>
    <collision>
      <origin rpy="0 0 0" xyz="0 0 0"/>
      <geometry>
        <mesh filename="link5.stl" scale="0.001 0.001 0.001"/>
      </geometry>
    </collision>
    <inertial>
      <origin rpy="0 0 0" xyz="0.05642 -0.00217 0.00002"/>
      <!--<origin xyz="-0.00658 -0.04717 0.00002" rpy="0 0 0"/>-->
      <mass value="0.44688"/>
      <inertia ixx="1.0" ixy="0.0" ixz="0.0" iyy="1.0" iyz="0.0" izz="1.0"/>
      <!--<inertia ixx="0.00030285" ixy="0.00000761" ixz="0.00000031" iyy="0.00022339" iyz="-0.00000001" izz="0.00039766" />-->
    </inertial>
  </link>
  <!-- Joint 5 -->
  <joint name="robot1/joint5" type="revolute">
    <parent link="robot1/link5"/>
    <child link="robot1/link6"/>
    <origin rpy="0 0 0" xyz="0.06300 0.04500 0.00000"/>
    <axis xyz="0 1 0"/>
    <limit effort="100" lower="-1.5707963267948966" upper="1.5707963267948966" velocity="3.03687"/>
    <dynamics damping="0.7"/>
  </joint>
  <!-- link 6 -->
  <link name="robot1/link6">
    <visual>
      <origin rpy="0 0 0" xyz="-0.034 -0.098 -0.028"/>
      <geometry>
        <mesh filename="link6_papras.stl" scale="0.001 0.001 0.001"/>
      </geometry>
      <material name="grey"/>
    </visual>
    <collision>
      <origin rpy="0 0 0" xyz="-0.034 -0.098 -0.028"/>
      <geometry>
        <mesh filename="link6_papras_simple.stl" scale="0.001 0.001 0.001"/>
      </geometry>
    </collision>
    <inertial>
      <origin rpy="0 0 0" xyz="0.06831 -0.04457 0.00000"/>
      <!--<origin xyz="-0.05469 0.00043 0.00000" rpy="0 0 0"/>-->
      <mass value="0.43273"/>
      <inertia ixx="1.0" ixy="0.0" ixz="0.0" iyy="1.0" iyz="0.0" izz="1.0"/>
      <!--<inertia ixx="0.00021512" ixy="0.00001009" ixz="0.00000000" iyy="0.00042827" iyz="0.00000000" izz="0.00051436" />-->
    </inertial>
  </link>
  <!-- Joint 6 -->
  <joint name="robot1/joint6" type="revolute">
    <parent link="robot1/link6"/>
    <child link="robot1/end_link"/>
    <origin rpy="0 0 0" xyz="0.12300 -0.04500 0.00000"/>
    <axis xyz="1 0 0"/>
    <limit effort="100" lower="-3.141592653589793" upper="3.141592653589793" velocity="3.03687"/>
    <dynamics damping="0.7"/>
  </joint>
  <!-- end link -->
  <link name="robot1/end_link">
    <visual>
      <origin rpy="0 0 0" xyz="0.0 0.0 0.0"/>
      <geometry>
        <mesh filename="end_link.stl" scale="0.001 0.001 0.001"/>
      </geometry>
      <material name="grey"/>
    </visual>
    <collision>
      <origin rpy="0 0 0" xyz="0.0 0.0 0.0"/>
      <geometry>
        <mesh filename="end_link.stl" scale="0.001 0.001 0.001"/>
      </geometry>
    </collision>
    <inertial>
      <origin rpy="0 0 0" xyz="0.00337 0.00000 0.00000"/>
      <mass value="0.01919"/>
      <inertia ixx="1.0" ixy="0.0" ixz="0.0" iyy="1.0" iyz="0.0" izz="1.0"/>
      <!--<inertia ixx="0.00000938" ixy="0.0" ixz="0.0" iyy="0.00000338" iyz="0.0" izz="0.00000635" />-->
    </inertial>
  </link>
  <!-- gripper main fixed joint-->
  <joint name="robot1/end_link_fixed" type="fixed">
    <parent link="robot1/end_link"/>
    <child link="robot1/gripper_main_link"/>
    <origin rpy="0 0 0" xyz="0.007 0.0 0.0"/>
  </joint>
  <!-- gripper main link -->
  <link name="robot1/gripper_main_link">
    <visual>
      <origin rpy="0 0 0" xyz="0 0 0"/>
      <geometry>
        <mesh filename="gripper_main_link.stl" scale="0.001 0.001 0.001"/>
      </geometry>
      <material name="grey"/>
    </visual>
    <collision>
      <origin rpy="0 0 0" xyz="0 0 0"/>
      <geometry>
        <mesh filename="gripper_main_link.stl" scale="0.001 0.001 0.001"/>
      </geometry>
    </collision>
    <inertial>
      <origin rpy="0 0 0" xyz="0.0 0.0 0.0"/>
      <mass value="0.509"/>
      <inertia ixx="1.0" ixy="0.0" ixz="0.0" iyy="1.0" iyz="0.0" izz="1.0"/>
    </inertial>
  </link>
  <!-- gripper joint -->
  <joint name="robot1/gripper" type="revolute">
    <axis xyz="0 0 1"/>
    <origin rpy="0 0 -0.4" xyz="0.0552 -0.0400 0"/>
    <parent link="robot1/gripper_main_link"/>
    <child link="robot1/gripper_link"/>
    <limit effort="100" lower="0.0" upper="1.15" velocity="3.03687"/>
    <dynamics damping="0.1" friction="0.0"/>
  </joint>
  <!-- gripper link -->
  <link name="robot1/gripper_link">
    <visual>
      <origin rpy="0 0 0" xyz="0 0 0"/>
      <geometry>
        <mesh filename="gripper_link.stl" scale="0.001 0.001 0.001"/>
      </geometry>
      <material name="grey"/>
    </visual>
    <collision>
      <origin rpy="0 0 0" xyz="0 0 0"/>
      <geometry>
        <mesh filename="gripper_link.stl" scale="0.001 0.001 0.001"/>
      </geometry>
      <material name="grey"/>
    </collision>
    <inertial>
      <origin rpy="0 0 0" xyz="0 0 0"/>
      <mass value="0.013"/>
      <inertia ixx="1.0" ixy="0.0" ixz="0.0" iyy="1.0" iyz="0.0" izz="1.0"/>
    </inertial>
  </link>
  <!-- gripper joint 1 -->
  <joint name="robot1/gripper_sub" type="revolute">
    <axis xyz="0 0 -1"/>
    <origin rpy="0 0 0.4" xyz="0.0552 0.0400 0"/>
    <parent link="robot1/gripper_main_link"/>
    <child link="robot1/gripper_sub_link"/>
    <limit effort="100" lower="0.0" upper="1.15" velocity="3.03687"/>
    <dynamics damping="0.1" friction="0.0"/>
    <mimic joint="robot1/gripper" multiplier="1"/>
  </joint>
  <!-- gripper 1 link -->
  <link name="robot1/gripper_sub_link">
    <visual>
      <origin rpy="0 0 0" xyz="0 0 0"/>
      <geometry>
        <mesh filename="gripper_sub_link.stl" scale="0.001 0.001 0.001"/>
      </geometry>
      <material name="grey"/>
    </visual>
    <collision>
      <origin rpy="0 0 0" xyz="0 0 0"/>
      <geometry>
        <mesh filename="gripper_sub_link.stl" scale="0.001 0.001 0.001"/>
      </geometry>
      <material name="grey"/>
    </collision>
    <inertial>
      <origin rpy="0 0 0" xyz="0 0 0"/>
      <mass value="0.013"/>
      <inertia ixx="1.0" ixy="0.0" ixz="0.0" iyy="1.0" iyz="0.0" izz="1.0"/>
    </inertial>
  </link>
  <!-- gripper main fixed joint-->
  <joint name="robot1/end_effector_joint" type="fixed">
    <parent link="robot1/gripper_main_link"/>
    <child link="robot1/end_effector_link"/>
    <origin rpy="0 0 0" xyz="0.14 0.0 0.0"/>
  </joint>
  <!-- End Effector -->
  <link name="robot1/end_effector_link">
    <visual>
      <origin rpy="0 0 0" xyz="0.0 0.0 0.0"/>
      <geometry>
        <box size="0.01 0.01 0.01"/>
      </geometry>
      <material name="red"/>
    </visual>
    <inertial>
      <origin rpy="0 0 0" xyz="0.0 0.0 0.0"/>
      <mass value="0.001"/>
      <inertia ixx="1.0" ixy="0.0" ixz="0.0" iyy="1.0" iyz="0.0" izz="1.0"/>
    </inertial>
  </link>
  <!-- camera link fixed joint -->
  <joint name="robot1/camera_fixed_joint" type="fixed">
    <parent link="robot1/gripper_main_link"/>
    <child link="robot1/camera_link"/>
    <origin rpy="-1.5707963267948966 0 -1.5707963267948966" xyz="0.0592 0.0167 0.04452"/>
  </joint>
  <!-- Camera Link -->
  <link name="robot1/camera_link">
    <visual>
      <origin rpy="1.5707963267948966 -1.5707963267948966 0" xyz="0 0 0"/>
      <geometry>
        <mesh filename="camera_mount.stl"/>
      </geometry>
      <material name="grey"/>
    </visual>
    <collision>
      <origin rpy="1.5707963267948966 -1.5707963267948966 0" xyz="0 0 0"/>
      <geometry>
        <mesh filename="camera_mount_simple.stl"/>
      </geometry>
    </collision>
    <inertial>
      <origin rpy="1.5707963267948966 -1.5707963267948966 0" xyz="0 0 0"/>
      <mass value="0.088"/>
      <inertia ixx="1.0" ixy="0.0" ixz="0.0" iyy="1.0" iyz="0.0" izz="1.0"/>
    </inertial>
  </link>
</robot>
